Workbook

Sheet Dashboard
A1: ALL AVAILABLE PRODUCT TYPES – NET MARGIN DASHBOARD
A4: Landing Value Excl GST | C4: Product Cost | E4: Gross Margin | G4: Operating Costs
B5: ='Product Type Summary'!E8 -> 0 | D5: ='Product Type Summary'!D8 -> 0 | F5: ='Product Type Summary'!F8 -> 0 | H5: ='Product Type Summary'!L8 -> 0
A8: Net Margin | C8: Net Margin % | E8: Target Net Margin % | G8: Items Below Target
B9: ='Product Type Summary'!M8 -> 0 | D9: ='Product Type Summary'!N8 -> 0 | F9: =Assumptions!B3 -> 0.3 | H9: ='Product Type Summary'!O8 -> 0
A12: Academic Year | B12: Product Type | C12: Items | D12: Landing Value | E12: Product Cost | F12: Gross Margin % | G12: Operating Cost | H12: Net Margin | I12: Net Margin %
A13: ='Product Type Summary'!A2 -> 2027-2028 | B13: ='Product Type Summary'!B2 -> Core | C13: ='Product Type Summary'!C2 -> 0 | D13: ='Product Type Summary'!E2 -> 0 | E13: ='Product Type Summary'!D2 -> 0 | F13: ='Product Type Summary'!G2 -> 0 | G13: ='Product Type Summary'!L2 -> 0 | H13: ='Product Type Summary'!M2 -> 0 | I13: ='Product Type Summary'!N2 -> 0
A14: ='Product Type Summary'!A3 -> 2027-2028 | B14: ='Product Type Summary'!B3 -> MINI | C14: ='Product Type Summary'!C3 -> 0 | D14: ='Product Type Summary'!E3 -> 0 | E14: ='Product Type Summary'!D3 -> 0 | F14: ='Product Type Summary'!G3 -> 0 | G14: ='Product Type Summary'!L3 -> 0 | H14: ='Product Type Summary'!M3 -> 0 | I14: ='Product Type Summary'!N3 -> 0
A15: ='Product Type Summary'!A4 -> 2027-2028 | B15: ='Product Type Summary'!B4 -> MINI+WB | C15: ='Product Type Summary'!C4 -> 0 | D15: ='Product Type Summary'!E4 -> 0 | E15: ='Product Type Summary'!D4 -> 0 | F15: ='Product Type Summary'!G4 -> 0 | G15: ='Product Type Summary'!L4 -> 0 | H15: ='Product Type Summary'!M4 -> 0 | I15: ='Product Type Summary'!N4 -> 0
A16: ='Product Type Summary'!A5 -> 2026-2027 | B16: ='Product Type Summary'!B5 -> Optional | C16: ='Product Type Summary'!C5 -> 0 | D16: ='Product Type Summary'!E5 -> 0 | E16: ='Product Type Summary'!D5 -> 0 | F16: ='Product Type Summary'!G5 -> 0 | G16: ='Product Type Summary'!L5 -> 0 | H16: ='Product Type Summary'!M5 -> 0 | I16: ='Product Type Summary'!N5 -> 0
A17: ='Product Type Summary'!A6 -> 2026-2027 | B17: ='Product Type Summary'!B6 -> CSR | C17: ='Product Type Summary'!C6 -> 0 | D17: ='Product Type Summary'!E6 -> 0 | E17: ='Product Type Summary'!D6 -> 0 | F17: ='Product Type Summary'!G6 -> 0 | G17: ='Product Type Summary'!L6 -> 0 | H17: ='Product Type Summary'!M6 -> 0 | I17: ='Product Type Summary'!N6 -> 0
A18: ='Product Type Summary'!A7 -> 2025-2026 | B18: ='Product Type Summary'!B7 -> CSR | C18: ='Product Type Summary'!C7 -> 0 | D18: ='Product Type Summary'!E7 -> 0 | E18: ='Product Type Summary'!D7 -> 0 | F18: ='Product Type Summary'!G7 -> 0 | G18: ='Product Type Summary'!L7 -> 0 | H18: ='Product Type Summary'!M7 -> 0 | I18: ='Product Type Summary'!N7 -> 0

Sheet Product Type Summary
A1: Academic Year | B1: Product Type | C1: Items | D1: Product Cost (₹) | E1: Landing Value Excl GST (₹) | F1: Gross Margin (₹) | G1: Gross Margin % | H1: Transport (₹) | I1: Warehouse (₹) | J1: Salary (₹) | K1: Additional Services (₹) | L1: Operating Cost (₹) | M1: Net Margin (₹) | N1: Net Margin % | O1: Items Below Target
A2: 2027-2028 | B2: Core | C2: =COUNTIFS('Margin Analysis'!$Y$2:$Y$645,$A2,'Margin Analysis'!$X$2:$X$645,$B2) -> 0 | D2: =SUMIFS('Margin Analysis'!$AB$2:$AB$645,'Margin Analysis'!$Y$2:$Y$645,$A2,'Margin Analysis'!$X$2:$X$645,$B2) -> 0 | E2: =SUMIFS('Margin Analysis'!$AA$2:$AA$645,'Margin Analysis'!$Y$2:$Y$645,$A2,'Margin Analysis'!$X$2:$X$645,$B2) -> 0 | F2: =E2-D2 -> 0 | G2: =IFERROR(F2/E2,0) -> 0 | H2: =SUMIFS('Margin Analysis'!$AG$2:$AG$645,'Margin Analysis'!$Y$2:$Y$645,$A2,'Margin Analysis'!$X$2:$X$645,$B2) -> 0 | I2: =SUMIFS('Margin Analysis'!$AH$2:$AH$645,'Margin Analysis'!$Y$2:$Y$645,$A2,'Margin Analysis'!$X$2:$X$645,$B2) -> 0 | J2: =SUMIFS('Margin Analysis'!$AI$2:$AI$645,'Margin Analysis'!$Y$2:$Y$645,$A2,'Margin Analysis'!$X$2:$X$645,$B2) -> 0 | K2: =SUMIFS('Margin Analysis'!$AJ$2:$AJ$645,'Margin Analysis'!$Y$2:$Y$645,$A2,'Margin Analysis'!$X$2:$X$645,$B2) -> 0 | L2: =SUM(H2:K2) -> 0 | M2: =F2-L2 -> 0 | N2: =IFERROR(M2/E2,0) -> 0 | O2: =COUNTIFS('Margin Analysis'!$Y$2:$Y$645,$A2,'Margin Analysis'!$X$2:$X$645,$B2,'Margin Analysis'!$AN$2:$AN$645,"<"&Assumptions!$B$3) -> 0
A3: 2027-2028 | B3: MINI | C3: =COUNTIFS('Margin Analysis'!$Y$2:$Y$645,$A3,'Margin Analysis'!$X$2:$X$645,$B3) -> 0 | D3: =SUMIFS('Margin Analysis'!$AB$2:$AB$645,'Margin Analysis'!$Y$2:$Y$645,$A3,'Margin Analysis'!$X$2:$X$645,$B3) -> 0 | E3: =SUMIFS('Margin Analysis'!$AA$2:$AA$645,'Margin Analysis'!$Y$2:$Y$645,$A3,'Margin Analysis'!$X$2:$X$645,$B3) -> 0 | F3: =E3-D3 -> 0 | G3: =IFERROR(F3/E3,0) -> 0 | H3: =SUMIFS('Margin Analysis'!$AG$2:$AG$645,'Margin Analysis'!$Y$2:$Y$645,$A3,'Margin Analysis'!$X$2:$X$645,$B3) -> 0 | I3: =SUMIFS('Margin Analysis'!$AH$2:$AH$645,'Margin Analysis'!$Y$2:$Y$645,$A3,'Margin Analysis'!$X$2:$X$645,$B3) -> 0 | J3: =SUMIFS('Margin Analysis'!$AI$2:$AI$645,'Margin Analysis'!$Y$2:$Y$645,$A3,'Margin Analysis'!$X$2:$X$645,$B3) -> 0 | K3: =SUMIFS('Margin Analysis'!$AJ$2:$AJ$645,'Margin Analysis'!$Y$2:$Y$645,$A3,'Margin Analysis'!$X$2:$X$645,$B3) -> 0 | L3: =SUM(H3:K3) -> 0 | M3: =F3-L3 -> 0 | N3: =IFERROR(M3/E3,0) -> 0 | O3: =COUNTIFS('Margin Analysis'!$Y$2:$Y$645,$A3,'Margin Analysis'!$X$2:$X$645,$B3,'Margin Analysis'!$AN$2:$AN$645,"<"&Assumptions!$B$3) -> 0
A4: 2027-2028 | B4: MINI+WB | C4: =COUNTIFS('Margin Analysis'!$Y$2:$Y$645,$A4,'Margin Analysis'!$X$2:$X$645,$B4) -> 0 | D4: =SUMIFS('Margin Analysis'!$AB$2:$AB$645,'Margin Analysis'!$Y$2:$Y$645,$A4,'Margin Analysis'!$X$2:$X$645,$B4) -> 0 | E4: =SUMIFS('Margin Analysis'!$AA$2:$AA$645,'Margin Analysis'!$Y$2:$Y$645,$A4,'Margin Analysis'!$X$2:$X$645,$B4) -> 0 | F4: =E4-D4 -> 0 | G4: =IFERROR(F4/E4,0) -> 0 | H4: =SUMIFS('Margin Analysis'!$AG$2:$AG$645,'Margin Analysis'!$Y$2:$Y$645,$A4,'Margin Analysis'!$X$2:$X$645,$B4) -> 0 | I4: =SUMIFS('Margin Analysis'!$AH$2:$AH$645,'Margin Analysis'!$Y$2:$Y$645,$A4,'Margin Analysis'!$X$2:$X$645,$B4) -> 0 | J4: =SUMIFS('Margin Analysis'!$AI$2:$AI$645,'Margin Analysis'!$Y$2:$Y$645,$A4,'Margin Analysis'!$X$2:$X$645,$B4) -> 0 | K4: =SUMIFS('Margin Analysis'!$AJ$2:$AJ$645,'Margin Analysis'!$Y$2:$Y$645,$A4,'Margin Analysis'!$X$2:$X$645,$B4) -> 0 | L4: =SUM(H4:K4) -> 0 | M4: =F4-L4 -> 0 | N4: =IFERROR(M4/E4,0) -> 0 | O4: =COUNTIFS('Margin Analysis'!$Y$2:$Y$645,$A4,'Margin Analysis'!$X$2:$X$645,$B4,'Margin Analysis'!$AN$2:$AN$645,"<"&Assumptions!$B$3) -> 0
A5: 2026-2027 | B5: Optional | C5: =COUNTIFS('Margin Analysis'!$Y$2:$Y$645,$A5,'Margin Analysis'!$X$2:$X$645,$B5) -> 0 | D5: =SUMIFS('Margin Analysis'!$AB$2:$AB$645,'Margin Analysis'!$Y$2:$Y$645,$A5,'Margin Analysis'!$X$2:$X$645,$B5) -> 0 | E5: =SUMIFS('Margin Analysis'!$AA$2:$AA$645,'Margin Analysis'!$Y$2:$Y$645,$A5,'Margin Analysis'!$X$2:$X$645,$B5) -> 0 | F5: =E5-D5 -> 0 | G5: =IFERROR(F5/E5,0) -> 0 | H5: =SUMIFS('Margin Analysis'!$AG$2:$AG$645,'Margin Analysis'!$Y$2:$Y$645,$A5,'Margin Analysis'!$X$2:$X$645,$B5) -> 0 | I5: =SUMIFS('Margin Analysis'!$AH$2:$AH$645,'Margin Analysis'!$Y$2:$Y$645,$A5,'Margin Analysis'!$X$2:$X$645,$B5) -> 0 | J5: =SUMIFS('Margin Analysis'!$AI$2:$AI$645,'Margin Analysis'!$Y$2:$Y$645,$A5,'Margin Analysis'!$X$2:$X$645,$B5) -> 0 | K5: =SUMIFS('Margin Analysis'!$AJ$2:$AJ$645,'Margin Analysis'!$Y$2:$Y$645,$A5,'Margin Analysis'!$X$2:$X$645,$B5) -> 0 | L5: =SUM(H5:K5) -> 0 | M5: =F5-L5 -> 0 | N5: =IFERROR(M5/E5,0) -> 0 | O5: =COUNTIFS('Margin Analysis'!$Y$2:$Y$645,$A5,'Margin Analysis'!$X$2:$X$645,$B5,'Margin Analysis'!$AN$2:$AN$645,"<"&Assumptions!$B$3) -> 0
A6: 2026-2027 | B6: CSR | C6: =COUNTIFS('Margin Analysis'!$Y$2:$Y$645,$A6,'Margin Analysis'!$X$2:$X$645,$B6) -> 0 | D6: =SUMIFS('Margin Analysis'!$AB$2:$AB$645,'Margin Analysis'!$Y$2:$Y$645,$A6,'Margin Analysis'!$X$2:$X$645,$B6) -> 0 | E6: =SUMIFS('Margin Analysis'!$AA$2:$AA$645,'Margin Analysis'!$Y$2:$Y$645,$A6,'Margin Analysis'!$X$2:$X$645,$B6) -> 0 | F6: =E6-D6 -> 0 | G6: =IFERROR(F6/E6,0) -> 0 | H6: =SUMIFS('Margin Analysis'!$AG$2:$AG$645,'Margin Analysis'!$Y$2:$Y$645,$A6,'Margin Analysis'!$X$2:$X$645,$B6) -> 0 | I6: =SUMIFS('Margin Analysis'!$AH$2:$AH$645,'Margin Analysis'!$Y$2:$Y$645,$A6,'Margin Analysis'!$X$2:$X$645,$B6) -> 0 | J6: =SUMIFS('Margin Analysis'!$AI$2:$AI$645,'Margin Analysis'!$Y$2:$Y$645,$A6,'Margin Analysis'!$X$2:$X$645,$B6) -> 0 | K6: =SUMIFS('Margin Analysis'!$AJ$2:$AJ$645,'Margin Analysis'!$Y$2:$Y$645,$A6,'Margin Analysis'!$X$2:$X$645,$B6) -> 0 | L6: =SUM(H6:K6) -> 0 | M6: =F6-L6 -> 0 | N6: =IFERROR(M6/E6,0) -> 0 | O6: =COUNTIFS('Margin Analysis'!$Y$2:$Y$645,$A6,'Margin Analysis'!$X$2:$X$645,$B6,'Margin Analysis'!$AN$2:$AN$645,"<"&Assumptions!$B$3) -> 0
A7: 2025-2026 | B7: CSR | C7: =COUNTIFS('Margin Analysis'!$Y$2:$Y$645,$A7,'Margin Analysis'!$X$2:$X$645,$B7) -> 0 | D7: =SUMIFS('Margin Analysis'!$AB$2:$AB$645,'Margin Analysis'!$Y$2:$Y$645,$A7,'Margin Analysis'!$X$2:$X$645,$B7) -> 0 | E7: =SUMIFS('Margin Analysis'!$AA$2:$AA$645,'Margin Analysis'!$Y$2:$Y$645,$A7,'Margin Analysis'!$X$2:$X$645,$B7) -> 0 | F7: =E7-D7 -> 0 | G7: =IFERROR(F7/E7,0) -> 0 | H7: =SUMIFS('Margin Analysis'!$AG$2:$AG$645,'Margin Analysis'!$Y$2:$Y$645,$A7,'Margin Analysis'!$X$2:$X$645,$B7) -> 0 | I7: =SUMIFS('Margin Analysis'!$AH$2:$AH$645,'Margin Analysis'!$Y$2:$Y$645,$A7,'Margin Analysis'!$X$2:$X$645,$B7) -> 0 | J7: =SUMIFS('Margin Analysis'!$AI$2:$AI$645,'Margin Analysis'!$Y$2:$Y$645,$A7,'Margin Analysis'!$X$2:$X$645,$B7) -> 0 | K7: =SUMIFS('Margin Analysis'!$AJ$2:$AJ$645,'Margin Analysis'!$Y$2:$Y$645,$A7,'Margin Analysis'!$X$2:$X$645,$B7) -> 0 | L7: =SUM(H7:K7) -> 0 | M7: =F7-L7 -> 0 | N7: =IFERROR(M7/E7,0) -> 0 | O7: =COUNTIFS('Margin Analysis'!$Y$2:$Y$645,$A7,'Margin Analysis'!$X$2:$X$645,$B7,'Margin Analysis'!$AN$2:$AN$645,"<"&Assumptions!$B$3) -> 0
A8: ALL | B8: TOTAL | C8: =SUM(C2:C7) -> 0 | D8: =SUM(D2:D7) -> 0 | E8: =SUM(E2:E7) -> 0 | F8: =SUM(F2:F7) -> 0 | G8: =IFERROR(F8/E8,0) -> 0 | H8: =SUM(H2:H7) -> 0 | I8: =SUM(I2:I7) -> 0 | J8: =SUM(J2:J7) -> 0 | K8: =SUM(K2:K7) -> 0 | L8: =SUM(L2:L7) -> 0 | M8: =SUM(M2:M7) -> 0 | N8: =IFERROR(M8/E8,0) -> 0 | O8: =SUM(O2:O7) -> 0

Sheet Academic Year Summary
A1: Academic Year | B1: Items | C1: Product Cost (₹) | D1: Landing Value Excl GST (₹) | E1: Gross Margin (₹) | F1: Gross Margin % | G1: Operating Cost (₹) | H1: Net Margin (₹) | I1: Net Margin % | J1: Items Below Target
A2: 2027-2028 | B2: =COUNTIF('Margin Analysis'!$Y$2:$Y$645,A2) -> 0 | C2: =SUMIF('Margin Analysis'!$Y$2:$Y$645,A2,'Margin Analysis'!$AB$2:$AB$645) -> 0 | D2: =SUMIF('Margin Analysis'!$Y$2:$Y$645,A2,'Margin Analysis'!$AA$2:$AA$645) -> 0 | E2: =D2-C2 -> 0 | F2: =IFERROR(E2/D2,0) -> 0 | G2: =SUMIF('Margin Analysis'!$Y$2:$Y$645,A2,'Margin Analysis'!$AK$2:$AK$645) -> 0 | H2: =SUMIF('Margin Analysis'!$Y$2:$Y$645,A2,'Margin Analysis'!$AM$2:$AM$645) -> 0 | I2: =IFERROR(H2/D2,0) -> 0 | J2: =COUNTIFS('Margin Analysis'!$Y$2:$Y$645,A2,'Margin Analysis'!$AN$2:$AN$645,"<"&Assumptions!$B$3) -> 0
A3: 2026-2027 | B3: =COUNTIF('Margin Analysis'!$Y$2:$Y$645,A3) -> 0 | C3: =SUMIF('Margin Analysis'!$Y$2:$Y$645,A3,'Margin Analysis'!$AB$2:$AB$645) -> 0 | D3: =SUMIF('Margin Analysis'!$Y$2:$Y$645,A3,'Margin Analysis'!$AA$2:$AA$645) -> 0 | E3: =D3-C3 -> 0 | F3: =IFERROR(E3/D3,0) -> 0 | G3: =SUMIF('Margin Analysis'!$Y$2:$Y$645,A3,'Margin Analysis'!$AK$2:$AK$645) -> 0 | H3: =SUMIF('Margin Analysis'!$Y$2:$Y$645,A3,'Margin Analysis'!$AM$2:$AM$645) -> 0 | I3: =IFERROR(H3/D3,0) -> 0 | J3: =COUNTIFS('Margin Analysis'!$Y$2:$Y$645,A3,'Margin Analysis'!$AN$2:$AN$645,"<"&Assumptions!$B$3) -> 0
A4: 2025-2026 | B4: =COUNTIF('Margin Analysis'!$Y$2:$Y$645,A4) -> 0 | C4: =SUMIF('Margin Analysis'!$Y$2:$Y$645,A4,'Margin Analysis'!$AB$2:$AB$645) -> 0 | D4: =SUMIF('Margin Analysis'!$Y$2:$Y$645,A4,'Margin Analysis'!$AA$2:$AA$645) -> 0 | E4: =D4-C4 -> 0 | F4: =IFERROR(E4/D4,0) -> 0 | G4: =SUMIF('Margin Analysis'!$Y$2:$Y$645,A4,'Margin Analysis'!$AK$2:$AK$645) -> 0 | H4: =SUMIF('Margin Analysis'!$Y$2:$Y$645,A4,'Margin Analysis'!$AM$2:$AM$645) -> 0 | I4: =IFERROR(H4/D4,0) -> 0 | J4: =COUNTIFS('Margin Analysis'!$Y$2:$Y$645,A4,'Margin Analysis'!$AN$2:$AN$645,"<"&Assumptions!$B$3) -> 0
A5: TOTAL | B5: =SUM(B2:B4) -> 0 | C5: =SUM(C2:C4) -> 0 | D5: =SUM(D2:D4) -> 0 | E5: =SUM(E2:E4) -> 0 | F5: =IFERROR(E5/D5,0) -> 0 | G5: =SUM(G2:G4) -> 0 | H5: =SUM(H2:H4) -> 0 | I5: =IFERROR(H5/D5,0) -> 0 | J5: =SUM(J2:J4) -> 0

Sheet Grade Summary
A1: Academic Year | B1: Product Type | C1: Grade | D1: Items | E1: Product Cost (₹) | F1: Landing Value Excl GST (₹) | G1: Gross Margin (₹) | H1: Gross Margin % | I1: Operating Cost (₹) | J1: Net Margin (₹) | K1: Net Margin % | L1: Items Below Target
A2: 2027-2028 | B2: Core | C2: Grade 1 | D2: =COUNTIFS('Margin Analysis'!$Y$2:$Y$645,$A2,'Margin Analysis'!$X$2:$X$645,$B2,'Margin Analysis'!$B$2:$B$645,$C2) -> 0 | E2: =SUMIFS('Margin Analysis'!$AB$2:$AB$645,'Margin Analysis'!$Y$2:$Y$645,$A2,'Margin Analysis'!$X$2:$X$645,$B2,'Margin Analysis'!$B$2:$B$645,$C2) -> 0 | F2: =SUMIFS('Margin Analysis'!$AA$2:$AA$645,'Margin Analysis'!$Y$2:$Y$645,$A2,'Margin Analysis'!$X$2:$X$645,$B2,'Margin Analysis'!$B$2:$B$645,$C2) -> 0 | G2: =F2-E2 -> 0 | H2: =IFERROR(G2/F2,0) -> 0 | I2: =SUMIFS('Margin Analysis'!$AK$2:$AK$645,'Margin Analysis'!$Y$2:$Y$645,$A2,'Margin Analysis'!$X$2:$X$645,$B2,'Margin Analysis'!$B$2:$B$645,$C2) -> 0 | J2: =SUMIFS('Margin Analysis'!$AM$2:$AM$645,'Margin Analysis'!$Y$2:$Y$645,$A2,'Margin Analysis'!$X$2:$X$645,$B2,'Margin Analysis'!$B$2:$B$645,$C2) -> 0 | K2: =IFERROR(J2/F2,0) -> 0 | L2: =COUNTIFS('Margin Analysis'!$Y$2:$Y$645,$A2,'Margin Analysis'!$X$2:$X$645,$B2,'Margin Analysis'!$B$2:$B$645,$C2,'Margin Analysis'!$AN$2:$AN$645,"<"&Assumptions!$B$3) -> 0
A3: 2027-2028 | B3: Core | C3: Grade 2 | D3: =COUNTIFS('Margin Analysis'!$Y$2:$Y$645,$A3,'Margin Analysis'!$X$2:$X$645,$B3,'Margin Analysis'!$B$2:$B$645,$C3) -> 0 | E3: =SUMIFS('Margin Analysis'!$AB$2:$AB$645,'Margin Analysis'!$Y$2:$Y$645,$A3,'Margin Analysis'!$X$2:$X$645,$B3,'Margin Analysis'!$B$2:$B$645,$C3) -> 0 | F3: =SUMIFS('Margin Analysis'!$AA$2:$AA$645,'Margin Analysis'!$Y$2:$Y$645,$A3,'Margin Analysis'!$X$2:$X$645,$B3,'Margin Analysis'!$B$2:$B$645,$C3) -> 0 | G3: =F3-E3 -> 0 | H3: =IFERROR(G3/F3,0) -> 0 | I3: =SUMIFS('Margin Analysis'!$AK$2:$AK$645,'Margin Analysis'!$Y$2:$Y$645,$A3,'Margin Analysis'!$X$2:$X$645,$B3,'Margin Analysis'!$B$2:$B$645,$C3) -> 0 | J3: =SUMIFS('Margin Analysis'!$AM$2:$AM$645,'Margin Analysis'!$Y$2:$Y$645,$A3,'Margin Analysis'!$X$2:$X$645,$B3,'Margin Analysis'!$B$2:$B$645,$C3) -> 0 | K3: =IFERROR(J3/F3,0) -> 0 | L3: =COUNTIFS('Margin Analysis'!$Y$2:$Y$645,$A3,'Margin Analysis'!$X$2:$X$645,$B3,'Margin Analysis'!$B$2:$B$645,$C3,'Margin Analysis'!$AN$2:$AN$645,"<"&Assumptions!$B$3) -> 0
A4: 2027-2028 | B4: Core | C4: Grade 3 | D4: =COUNTIFS('Margin Analysis'!$Y$2:$Y$645,$A4,'Margin Analysis'!$X$2:$X$645,$B4,'Margin Analysis'!$B$2:$B$645,$C4) -> 0 | E4: =SUMIFS('Margin Analysis'!$AB$2:$AB$645,'Margin Analysis'!$Y$2:$Y$645,$A4,'Margin Analysis'!$X$2:$X$645,$B4,'Margin Analysis'!$B$2:$B$645,$C4) -> 0 | F4: =SUMIFS('Margin Analysis'!$AA$2:$AA$645,'Margin Analysis'!$Y$2:$Y$645,$A4,'Margin Analysis'!$X$2:$X$645,$B4,'Margin Analysis'!$B$2:$B$645,$C4) -> 0 | G4: =F4-E4 -> 0 | H4: =IFERROR(G4/F4,0) -> 0 | I4: =SUMIFS('Margin Analysis'!$AK$2:$AK$645,'Margin Analysis'!$Y$2:$Y$645,$A4,'Margin Analysis'!$X$2:$X$645,$B4,'Margin Analysis'!$B$2:$B$645,$C4) -> 0 | J4: =SUMIFS('Margin Analysis'!$AM$2:$AM$645,'Margin Analysis'!$Y$2:$Y$645,$A4,'Margin Analysis'!$X$2:$X$645,$B4,'Margin Analysis'!$B$2:$B$645,$C4) -> 0 | K4: =IFERROR(J4/F4,0) -> 0 | L4: =COUNTIFS('Margin Analysis'!$Y$2:$Y$645,$A4,'Margin Analysis'!$X$2:$X$645,$B4,'Margin Analysis'!$B$2:$B$645,$C4,'Margin Analysis'!$AN$2:$AN$645,"<"&Assumptions!$B$3) -> 0
A5: 2027-2028 | B5: Core | C5: Grade 4 | D5: =COUNTIFS('Margin Analysis'!$Y$2:$Y$645,$A5,'Margin Analysis'!$X$2:$X$645,$B5,'Margin Analysis'!$B$2:$B$645,$C5) -> 0 | E5: =SUMIFS('Margin Analysis'!$AB$2:$AB$645,'Margin Analysis'!$Y$2:$Y$645,$A5,'Margin Analysis'!$X$2:$X$645,$B5,'Margin Analysis'!$B$2:$B$645,$C5) -> 0 | F5: =SUMIFS('Margin Analysis'!$AA$2:$AA$645,'Margin Analysis'!$Y$2:$Y$645,$A5,'Margin Analysis'!$X$2:$X$645,$B5,'Margin Analysis'!$B$2:$B$645,$C5) -> 0 | G5: =F5-E5 -> 0 | H5: =IFERROR(G5/F5,0) -> 0 | I5: =SUMIFS('Margin Analysis'!$AK$2:$AK$645,'Margin Analysis'!$Y$2:$Y$645,$A5,'Margin Analysis'!$X$2:$X$645,$B5,'Margin Analysis'!$B$2:$B$645,$C5) -> 0 | J5: =SUMIFS('Margin Analysis'!$AM$2:$AM$645,'Margin Analysis'!$Y$2:$Y$645,$A5,'Margin Analysis'!$X$2:$X$645,$B5,'Margin Analysis'!$B$2:$B$645,$C5) -> 0 | K5: =IFERROR(J5/F5,0) -> 0 | L5: =COUNTIFS('Margin Analysis'!$Y$2:$Y$645,$A5,'Margin Analysis'!$X$2:$X$645,$B5,'Margin Analysis'!$B$2:$B$645,$C5,'Margin Analysis'!$AN$2:$AN$645,"<"&Assumptions!$B$3) -> 0
A6: 2027-2028 | B6: Core | C6: Grade 5 | D6: =COUNTIFS('Margin Analysis'!$Y$2:$Y$645,$A6,'Margin Analysis'!$X$2:$X$645,$B6,'Margin Analysis'!$B$2:$B$645,$C6) -> 0 | E6: =SUMIFS('Margin Analysis'!$AB$2:$AB$645,'Margin Analysis'!$Y$2:$Y$645,$A6,'Margin Analysis'!$X$2:$X$645,$B6,'Margin Analysis'!$B$2:$B$645,$C6) -> 0 | F6: =SUMIFS('Margin Analysis'!$AA$2:$AA$645,'Margin Analysis'!$Y$2:$Y$645,$A6,'Margin Analysis'!$X$2:$X$645,$B6,'Margin Analysis'!$B$2:$B$645,$C6) -> 0 | G6: =F6-E6 -> 0 | H6: =IFERROR(G6/F6,0) -> 0 | I6: =SUMIFS('Margin Analysis'!$AK$2:$AK$645,'Margin Analysis'!$Y$2:$Y$645,$A6,'Margin Analysis'!$X$2:$X$645,$B6,'Margin Analysis'!$B$2:$B$645,$C6) -> 0 | J6: =SUMIFS('Margin Analysis'!$AM$2:$AM$645,'Margin Analysis'!$Y$2:$Y$645,$A6,'Margin Analysis'!$X$2:$X$645,$B6,'Margin Analysis'!$B$2:$B$645,$C6) -> 0 | K6: =IFERROR(J6/F6,0) -> 0 | L6: =COUNTIFS('Margin Analysis'!$Y$2:$Y$645,$A6,'Margin Analysis'!$X$2:$X$645,$B6,'Margin Analysis'!$B$2:$B$645,$C6,'Margin Analysis'!$AN$2:$AN$645,"<"&Assumptions!$B$3) -> 0
A7: 2027-2028 | B7: Core | C7: Grade 6 | D7: =COUNTIFS('Margin Analysis'!$Y$2:$Y$645,$A7,'Margin Analysis'!$X$2:$X$645,$B7,'Margin Analysis'!$B$2:$B$645,$C7) -> 0 | E7: =SUMIFS('Margin Analysis'!$AB$2:$AB$645,'Margin Analysis'!$Y$2:$Y$645,$A7,'Margin Analysis'!$X$2:$X$645,$B7,'Margin Analysis'!$B$2:$B$645,$C7) -> 0 | F7: =SUMIFS('Margin Analysis'!$AA$2:$AA$645,'Margin Analysis'!$Y$2:$Y$645,$A7,'Margin Analysis'!$X$2:$X$645,$B7,'Margin Analysis'!$B$2:$B$645,$C7) -> 0 | G7: =F7-E7 -> 0 | H7: =IFERROR(G7/F7,0) -> 0 | I7: =SUMIFS('Margin Analysis'!$AK$2:$AK$645,'Margin Analysis'!$Y$2:$Y$645,$A7,'Margin Analysis'!$X$2:$X$645,$B7,'Margin Analysis'!$B$2:$B$645,$C7) -> 0 | J7: =SUMIFS('Margin Analysis'!$AM$2:$AM$645,'Margin Analysis'!$Y$2:$Y$645,$A7,'Margin Analysis'!$X$2:$X$645,$B7,'Margin Analysis'!$B$2:$B$645,$C7) -> 0 | K7: =IFERROR(J7/F7,0) -> 0 | L7: =COUNTIFS('Margin Analysis'!$Y$2:$Y$645,$A7,'Margin Analysis'!$X$2:$X$645,$B7,'Margin Analysis'!$B$2:$B$645,$C7,'Margin Analysis'!$AN$2:$AN$645,"<"&Assumptions!$B$3) -> 0
A8: 2027-2028 | B8: Core | C8: Grade 7 | D8: =COUNTIFS('Margin Analysis'!$Y$2:$Y$645,$A8,'Margin Analysis'!$X$2:$X$645,$B8,'Margin Analysis'!$B$2:$B$645,$C8) -> 0 | E8: =SUMIFS('Margin Analysis'!$AB$2:$AB$645,'Margin Analysis'!$Y$2:$Y$645,$A8,'Margin Analysis'!$X$2:$X$645,$B8,'Margin Analysis'!$B$2:$B$645,$C8) -> 0 | F8: =SUMIFS('Margin Analysis'!$AA$2:$AA$645,'Margin Analysis'!$Y$2:$Y$645,$A8,'Margin Analysis'!$X$2:$X$645,$B8,'Margin Analysis'!$B$2:$B$645,$C8) -> 0 | G8: =F8-E8 -> 0 | H8: =IFERROR(G8/F8,0) -> 0 | I8: =SUMIFS('Margin Analysis'!$AK$2:$AK$645,'Margin Analysis'!$Y$2:$Y$645,$A8,'Margin Analysis'!$X$2:$X$645,$B8,'Margin Analysis'!$B$2:$B$645,$C8) -> 0 | J8: =SUMIFS('Margin Analysis'!$AM$2:$AM$645,'Margin Analysis'!$Y$2:$Y$645,$A8,'Margin Analysis'!$X$2:$X$645,$B8,'Margin Analysis'!$B$2:$B$645,$C8) -> 0 | K8: =IFERROR(J8/F8,0) -> 0 | L8: =COUNTIFS('Margin Analysis'!$Y$2:$Y$645,$A8,'Margin Analysis'!$X$2:$X$645,$B8,'Margin Analysis'!$B$2:$B$645,$C8,'Margin Analysis'!$AN$2:$AN$645,"<"&Assumptions!$B$3) -> 0
A9: 2027-2028 | B9: Core | C9: Grade 8 | D9: =COUNTIFS('Margin Analysis'!$Y$2:$Y$645,$A9,'Margin Analysis'!$X$2:$X$645,$B9,'Margin Analysis'!$B$2:$B$645,$C9) -> 0 | E9: =SUMIFS('Margin Analysis'!$AB$2:$AB$645,'Margin Analysis'!$Y$2:$Y$645,$A9,'Margin Analysis'!$X$2:$X$645,$B9,'Margin Analysis'!$B$2:$B$645,$C9) -> 0 | F9: =SUMIFS('Margin Analysis'!$AA$2:$AA$645,'Margin Analysis'!$Y$2:$Y$645,$A9,'Margin Analysis'!$X$2:$X$645,$B9,'Margin Analysis'!$B$2:$B$645,$C9) -> 0 | G9: =F9-E9 -> 0 | H9: =IFERROR(G9/F9,0) -> 0 | I9: =SUMIFS('Margin Analysis'!$AK$2:$AK$645,'Margin Analysis'!$Y$2:$Y$645,$A9,'Margin Analysis'!$X$2:$X$645,$B9,'Margin Analysis'!$B$2:$B$645,$C9) -> 0 | J9: =SUMIFS('Margin Analysis'!$AM$2:$AM$645,'Margin Analysis'!$Y$2:$Y$645,$A9,'Margin Analysis'!$X$2:$X$645,$B9,'Margin Analysis'!$B$2:$B$645,$C9) -> 0 | K9: =IFERROR(J9/F9,0) -> 0 | L9: =COUNTIFS('Margin Analysis'!$Y$2:$Y$645,$A9,'Margin Analysis'!$X$2:$X$645,$B9,'Margin Analysis'!$B$2:$B$645,$C9,'Margin Analysis'!$AN$2:$AN$645,"<"&Assumptions!$B$3) -> 0
A10: 2027-2028 | B10: Core | C10: K1 | D10: =COUNTIFS('Margin Analysis'!$Y$2:$Y$645,$A10,'Margin Analysis'!$X$2:$X$645,$B10,'Margin Analysis'!$B$2:$B$645,$C10) -> 0 | E10: =SUMIFS('Margin Analysis'!$AB$2:$AB$645,'Margin Analysis'!$Y$2:$Y$645,$A10,'Margin Analysis'!$X$2:$X$645,$B10,'Margin Analysis'!$B$2:$B$645,$C10) -> 0 | F10: =SUMIFS('Margin Analysis'!$AA$2:$AA$645,'Margin Analysis'!$Y$2:$Y$645,$A10,'Margin Analysis'!$X$2:$X$645,$B10,'Margin Analysis'!$B$2:$B$645,$C10) -> 0 | G10: =F10-E10 -> 0 | H10: =IFERROR(G10/F10,0) -> 0 | I10: =SUMIFS('Margin Analysis'!$AK$2:$AK$645,'Margin Analysis'!$Y$2:$Y$645,$A10,'Margin Analysis'!$X$2:$X$645,$B10,'Margin Analysis'!$B$2:$B$645,$C10) -> 0 | J10: =SUMIFS('Margin Analysis'!$AM$2:$AM$645,'Margin Analysis'!$Y$2:$Y$645,$A10,'Margin Analysis'!$X$2:$X$645,$B10,'Margin Analysis'!$B$2:$B$645,$C10) -> 0 | K10: =IFERROR(J10/F10,0) -> 0 | L10: =COUNTIFS('Margin Analysis'!$Y$2:$Y$645,$A10,'Margin Analysis'!$X$2:$X$645,$B10,'Margin Analysis'!$B$2:$B$645,$C10,'Margin Analysis'!$AN$2:$AN$645,"<"&Assumptions!$B$3) -> 0
A11: 2027-2028 | B11: Core | C11: K2 | D11: =COUNTIFS('Margin Analysis'!$Y$2:$Y$645,$A11,'Margin Analysis'!$X$2:$X$645,$B11,'Margin Analysis'!$B$2:$B$645,$C11) -> 0 | E11: =SUMIFS('Margin Analysis'!$AB$2:$AB$645,'Margin Analysis'!$Y$2:$Y$645,$A11,'Margin Analysis'!$X$2:$X$645,$B11,'Margin Analysis'!$B$2:$B$645,$C11) -> 0 | F11: =SUMIFS('Margin Analysis'!$AA$2:$AA$645,'Margin Analysis'!$Y$2:$Y$645,$A11,'Margin Analysis'!$X$2:$X$645,$B11,'Margin Analysis'!$B$2:$B$645,$C11) -> 0 | G11: =F11-E11 -> 0 | H11: =IFERROR(G11/F11,0) -> 0 | I11: =SUMIFS('Margin Analysis'!$AK$2:$AK$645,'Margin Analysis'!$Y$2:$Y$645,$A11,'Margin Analysis'!$X$2:$X$645,$B11,'Margin Analysis'!$B$2:$B$645,$C11) -> 0 | J11: =SUMIFS('Margin Analysis'!$AM$2:$AM$645,'Margin Analysis'!$Y$2:$Y$645,$A11,'Margin Analysis'!$X$2:$X$645,$B11,'Margin Analysis'!$B$2:$B$645,$C11) -> 0 | K11: =IFERROR(J11/F11,0) -> 0 | L11: =COUNTIFS('Margin Analysis'!$Y$2:$Y$645,$A11,'Margin Analysis'!$X$2:$X$645,$B11,'Margin Analysis'!$B$2:$B$645,$C11,'Margin Analysis'!$AN$2:$AN$645,"<"&Assumptions!$B$3) -> 0
A12: 2027-2028 | B12: Core | C12: Nursery | D12: =COUNTIFS('Margin Analysis'!$Y$2:$Y$645,$A12,'Margin Analysis'!$X$2:$X$645,$B12,'Margin Analysis'!$B$2:$B$645,$C12) -> 0 | E12: =SUMIFS('Margin Analysis'!$AB$2:$AB$645,'Margin Analysis'!$Y$2:$Y$645,$A12,'Margin Analysis'!$X$2:$X$645,$B12,'Margin Analysis'!$B$2:$B$645,$C12) -> 0 | F12: =SUMIFS('Margin Analysis'!$AA$2:$AA$645,'Margin Analysis'!$Y$2:$Y$645,$A12,'Margin Analysis'!$X$2:$X$645,$B12,'Margin Analysis'!$B$2:$B$645,$C12) -> 0 | G12: =F12-E12 -> 0 | H12: =IFERROR(G12/F12,0) -> 0 | I12: =SUMIFS('Margin Analysis'!$AK$2:$AK$645,'Margin Analysis'!$Y$2:$Y$645,$A12,'Margin Analysis'!$X$2:$X$645,$B12,'Margin Analysis'!$B$2:$B$645,$C12) -> 0 | J12: =SUMIFS('Margin Analysis'!$AM$2:$AM$645,'Margin Analysis'!$Y$2:$Y$645,$A12,'Margin Analysis'!$X$2:$X$645,$B12,'Margin Analysis'!$B$2:$B$645,$C12) -> 0 | K12: =IFERROR(J12/F12,0) -> 0 | L12: =COUNTIFS('Margin Analysis'!$Y$2:$Y$645,$A12,'Margin Analysis'!$X$2:$X$645,$B12,'Margin Analysis'!$B$2:$B$645,$C12,'Margin Analysis'!$AN$2:$AN$645,"<"&Assumptions!$B$3) -> 0
A13: 2027-2028 | B13: Core | C13: Pre Nursery | D13: =COUNTIFS('Margin Analysis'!$Y$2:$Y$645,$A13,'Margin Analysis'!$X$2:$X$645,$B13,'Margin Analysis'!$B$2:$B$645,$C13) -> 0 | E13: =SUMIFS('Margin Analysis'!$AB$2:$AB$645,'Margin Analysis'!$Y$2:$Y$645,$A13,'Margin Analysis'!$X$2:$X$645,$B13,'Margin Analysis'!$B$2:$B$645,$C13) -> 0 | F13: =SUMIFS('Margin Analysis'!$AA$2:$AA$645,'Margin Analysis'!$Y$2:$Y$645,$A13,'Margin Analysis'!$X$2:$X$645,$B13,'Margin Analysis'!$B$2:$B$645,$C13) -> 0 | G13: =F13-E13 -> 0 | H13: =IFERROR(G13/F13,0) -> 0 | I13: =SUMIFS('Margin Analysis'!$AK$2:$AK$645,'Margin Analysis'!$Y$2:$Y$645,$A13,'Margin Analysis'!$X$2:$X$645,$B13,'Margin Analysis'!$B$2:$B$645,$C13) -> 0 | J13: =SUMIFS('Margin Analysis'!$AM$2:$AM$645,'Margin Analysis'!$Y$2:$Y$645,$A13,'Margin Analysis'!$X$2:$X$645,$B13,'Margin Analysis'!$B$2:$B$645,$C13) -> 0 | K13: =IFERROR(J13/F13,0) -> 0 | L13: =COUNTIFS('Margin Analysis'!$Y$2:$Y$645,$A13,'Margin Analysis'!$X$2:$X$645,$B13,'Margin Analysis'!$B$2:$B$645,$C13,'Margin Analysis'!$AN$2:$AN$645,"<"&Assumptions!$B$3) -> 0
... A68: 2025-2026 | B68: CSR | C68: Grade 9 | D68: =COUNTIFS('Margin Analysis'!$Y$2:$Y$645,$A68,'Margin Analysis'!$X$2:$X$645,$B68,'Margin Analysis'!$B$2:$B$645,$C68) -> 0 | E68: =SUMIFS('Margin Analysis'!$AB$2:$AB$645,'Margin Analysis'!$Y$2:$Y$645,$A68,'Margin Analysis'!$X$2:$X$645,$B68,'Margin Analysis'!$B$2:$B$645,$C68) -> 0 | F68: =SUMIFS('Margin Analysis'!$AA$2:$AA$645,'Margin Analysis'!$Y$2:$Y$645,$A68,'Margin Analysis'!$X$2:$X$645,$B68,'Margin Analysis'!$B$2:$B$645,$C68) -> 0 | G68: =F68-E68 -> 0 | H68: =IFERROR(G68/F68,0) -> 0 | I68: =SUMIFS('Margin Analysis'!$AK$2:$AK$645,'Margin Analysis'!$Y$2:$Y$645,$A68,'Margin Analysis'!$X$2:$X$645,$B68,'Margin Analysis'!$B$2:$B$645,$C68) -> 0 | J68: =SUMIFS('Margin Analysis'!$AM$2:$AM$645,'Margin Analysis'!$Y$2:$Y$645,$A68,'Margin Analysis'!$X$2:$X$645,$B68,'Margin Analysis'!$B$2:$B$645,$C68) -> 0 | K68: =IFERROR(J68/F68,0) -> 0 | L68: =COUNTIFS('Margin Analysis'!$Y$2:$Y$645,$A68,'Margin Analysis'!$X$2:$X$645,$B68,'Margin Analysis'!$B$2:$B$645,$C68,'Margin Analysis'!$AN$2:$AN$645,"<"&Assumptions!$B$3) -> 0

Sheet Margin Analysis
A1: Product Name | B1: Grades | C1: Subjects | D1: Item Name | E1: Ratio | F1: Item Type | G1: Edition | H1: Type | I1: Core Kit SKU | J1: CP | K1: Aprox Margin | L1: CP + Margin | M1: GST % | N1: GST Value | O1: Base Price with GST | P1: Base % | Q1: Base Bundle | R1: MRP Bundle | S1: MRP IND | T1: Value Type | U1: Selling Price | V1: Selling Price After Discount @30% (₹) | W1: HSN Code | X1: Product Type | Y1: Academic Year | Z1: Allocated Landing Price (Incl GST) (₹) | AA1: Landing Price (Excl GST) (₹) | AB1: Cost Price (₹) | AC1: Gross Margin (₹) | AD1: Gross Margin % | AE1: Markup on Cost % | AF1: Gross Margin Status | AG1: Transportation Cost (₹) | AH1: Warehouse & Facility Cost (₹) | AI1: Employee Salary Cost (₹) | AJ1: Additional Services Cost (₹) | AK1: Total Operating Cost (₹) | AL1: Operating Cost % Applied | AM1: Net Margin (₹) | AN1: Net Margin % | AO1: Net Margin Status
A2: Corekit AY 2027-2028 | B2: Grade 1 | C2: Maths | D2: T1_G1_Math_Scholars_TB B2B (27) | E2: 1:1 | F2: Book | G2: 2027-2028 | H2: Term 1 | I2: 4000011860 | J2: 44.16 | L2: =J2+K2 -> 44.16 | M2: 0 | N2: =M2*L2 -> 0 | O2: =L2+N2 -> 44.16 | P2: =IFERROR(O2/Q2,"") -> 0.13933676 | Q2: =SUMIFS(O:O,T:T,T2,B:B,B2,A:A,A2,G:G,G2,E:E,E2) -> 316.93 | R2: =V2-SUMIFS(Q:Q,A:A,A2,B:B,B2,G:G,G2,E:E,E2,T:T,"Fixed Price ( Base Price with GST)") -> 2402.3364 | S2: =IF(T2="Fixed Price ( Base Price with GST)",O2,P2*R2) -> 334.73378 | T2: Based on Base % | U2: 4499 | V2: =IFERROR(U2*(1-30%),0) -> 3149.3 | W2: 490110 | X2: Core | Y2: =IFERROR(S2,0) -> 334.73378 | Z2: =IF(ISNUMBER(S2),S2,0) -> 334.73378 | AA2: =IFERROR(Z2/(1+M2),Z2) -> 334.73378 | AB2: =IF(ISNUMBER(J2),J2,0) -> 44.16 | AC2: =AA2-AB2 -> 290.57378 | AD2: =IFERROR(AC2/AA2,0) -> 0.86807426 | AE2: =IFERROR(AC2/AB2,0) -> 6.5800221 | AF2: =IF(AD2>=Assumptions!$B$3,"OK","Review") -> OK | AG2: =IFERROR(IF(Assumptions!$B$13="Cost Price",AB2,AA2)*SUMIF(Assumptions!$A$6:$A$10,X2,Assumptions!$B$6:$B$10),0) -> 26.778702 | AH2: =IFERROR(IF(Assumptions!$B$13="Cost Price",AB2,AA2)*SUMIF(Assumptions!$A$6:$A$10,X2,Assumptions!$C$6:$C$10),0) -> 16.736689 | AI2: =IFERROR(IF(Assumptions!$B$13="Cost Price",AB2,AA2)*SUMIF(Assumptions!$A$6:$A$10,X2,Assumptions!$D$6:$D$10),0) -> 33.473378 | AJ2: 33.473378 | AK2: =SUM(AG2:AJ2) -> 110.46215 | AL2: 0.33 | AM2: =AC2-AK2 -> 180.11163 | AN2: =IFERROR(AM2/AA2,0) -> 0.53807426 | AO2: =IF(AN2>=Assumptions!$B$3,"OK","Review") -> OK
A3: Corekit AY 2027-2028 | B3: Grade 1 | C3: Maths | D3: T1_G1_Math_Scholars_WB B2B (27) | E3: 1:1 | F3: Book | G3: 2027-2028 | H3: Term 1 | I3: 4000011852 | J3: 20.94 | L3: =J3+K3 -> 20.94 | M3: 0 | N3: =M3*L3 -> 0 | O3: =L3+N3 -> 20.94 | P3: =IFERROR(O3/Q3,"") -> 0.066071372 | Q3: =SUMIFS(O:O,T:T,T3,B:B,B3,A:A,A3,G:G,G3,E:E,E3) -> 316.93 | R3: =V3-SUMIFS(Q:Q,A:A,A3,B:B,B3,G:G,G3,E:E,E3,T:T,"Fixed Price ( Base Price with GST)") -> 2402.3364 | S3: =IF(T3="Fixed Price ( Base Price with GST)",O3,P3*R3) -> 158.72566 | T3: Based on Base % | U3: 4499 | V3: =IFERROR(U3*(1-30%),0) -> 3149.3 | W3: 490110 | X3: Core | Y3: =IFERROR(S3,0) -> 158.72566 | Z3: =IF(ISNUMBER(S3),S3,0) -> 158.72566 | AA3: =IFERROR(Z3/(1+M3),Z3) -> 158.72566 | AB3: =IF(ISNUMBER(J3),J3,0) -> 20.94 | AC3: =AA3-AB3 -> 137.78566 | AD3: =IFERROR(AC3/AA3,0) -> 0.86807426 | AE3: =IFERROR(AC3/AB3,0) -> 6.5800221 | AF3: =IF(AD3>=Assumptions!$B$3,"OK","Review") -> OK | AG3: =IFERROR(IF(Assumptions!$B$13="Cost Price",AB3,AA3)*SUMIF(Assumptions!$A$6:$A$10,X3,Assumptions!$B$6:$B$10),0) -> 12.698053 | AH3: =IFERROR(IF(Assumptions!$B$13="Cost Price",AB3,AA3)*SUMIF(Assumptions!$A$6:$A$10,X3,Assumptions!$C$6:$C$10),0) -> 7.9362831 | AI3: =IFERROR(IF(Assumptions!$B$13="Cost Price",AB3,AA3)*SUMIF(Assumptions!$A$6:$A$10,X3,Assumptions!$D$6:$D$10),0) -> 15.872566 | AJ3: 24.790219 | AK3: =SUM(AG3:AJ3) -> 61.297122 | AL3: 0.33 | AM3: =AC3-AK3 -> 76.488541 | AN3: =IFERROR(AM3/AA3,0) -> 0.48189146 | AO3: =IF(AN3>=Assumptions!$B$3,"OK","Review") -> OK
A4: Corekit AY 2027-2028 | B4: Grade 1 | C4: English | D4: Annual_G1_English_RB B2B (27) | E4: 1:1 | F4: Book | G4: 2027-2028 | H4: Term 1 | I4: 4000011794 | J4: 19.56 | L4: =J4+K4 -> 19.56 | M4: 0 | N4: =M4*L4 -> 0 | O4: =L4+N4 -> 19.56 | P4: =IFERROR(O4/Q4,"") -> 0.061717098 | Q4: =SUMIFS(O:O,T:T,T4,B:B,B4,A:A,A4,G:G,G4,E:E,E4) -> 316.93 | R4: =V4-SUMIFS(Q:Q,A:A,A4,B:B,B4,G:G,G4,E:E,E4,T:T,"Fixed Price ( Base Price with GST)") -> 2402.3364 | S4: =IF(T4="Fixed Price ( Base Price with GST)",O4,P4*R4) -> 148.26523 | T4: Based on Base % | U4: 4499 | V4: =IFERROR(U4*(1-30%),0) -> 3149.3 | W4: 490110 | X4: Core | Y4: =IFERROR(S4,0) -> 148.26523 | Z4: =IF(ISNUMBER(S4),S4,0) -> 148.26523 | AA4: =IFERROR(Z4/(1+M4),Z4) -> 148.26523 | AB4: =IF(ISNUMBER(J4),J4,0) -> 19.56 | AC4: =AA4-AB4 -> 128.70523 | AD4: =IFERROR(AC4/AA4,0) -> 0.86807426 | AE4: =IFERROR(AC4/AB4,0) -> 6.5800221 | AF4: =IF(AD4>=Assumptions!$B$3,"OK","Review") -> OK | AG4: =IFERROR(IF(Assumptions!$B$13="Cost Price",AB4,AA4)*SUMIF(Assumptions!$A$6:$A$10,X4,Assumptions!$B$6:$B$10),0) -> 11.861219 | AH4: =IFERROR(IF(Assumptions!$B$13="Cost Price",AB4,AA4)*SUMIF(Assumptions!$A$6:$A$10,X4,Assumptions!$C$6:$C$10),0) -> 7.4132616 | AI4: =IFERROR(IF(Assumptions!$B$13="Cost Price",AB4,AA4)*SUMIF(Assumptions!$A$6:$A$10,X4,Assumptions!$D$6:$D$10),0) -> 14.826523 | AJ4: 23.15648 | AK4: =SUM(AG4:AJ4) -> 57.257483 | AL4: 0.33 | AM4: =AC4-AK4 -> 71.447749 | AN4: =IFERROR(AM4/AA4,0) -> 0.48189146 | AO4: =IF(AN4>=Assumptions!$B$3,"OK","Review") -> OK
A5: Corekit AY 2027-2028 | B5: Grade 1 | C5: English | D5: T1_G1_English_RC B2B (27) | E5: 1:1 | F5: Workbook | G5: 2027-2028 | H5: Term 1 | I5: 4000011783 | J5: 60.15 | L5: =J5+K5 -> 60.15 | M5: 0 | N5: =M5*L5 -> 0 | O5: =L5+N5 -> 60.15 | P5: =IFERROR(O5/Q5,"") -> 0.18978954 | Q5: =SUMIFS(O:O,T:T,T5,B:B,B5,A:A,A5,G:G,G5,E:E,E5) -> 316.93 | R5: =V5-SUMIFS(Q:Q,A:A,A5,B:B,B5,G:G,G5,E:E,E5,T:T,"Fixed Price ( Base Price with GST)") -> 2402.3364 | S5: =IF(T5="Fixed Price ( Base Price with GST)",O5,P5*R5) -> 455.93833 | T5: Based on Base % | U5: 4499 | V5: =IFERROR(U5*(1-30%),0) -> 3149.3 | W5: 490110 | X5: Core | Y5: =IFERROR(S5,0) -> 455.93833 | Z5: =IF(ISNUMBER(S5),S5,0) -> 455.93833 | AA5: =IFERROR(Z5/(1+M5),Z5) -> 455.93833 | AB5: =IF(ISNUMBER(J5),J5,0) -> 60.15 | AC5: =AA5-AB5 -> 395.78833 | AD5: =IFERROR(AC5/AA5,0) -> 0.86807426 | AE5: =IFERROR(AC5/AB5,0) -> 6.5800221 | AF5: =IF(AD5>=Assumptions!$B$3,"OK","Review") -> OK | AG5: =IFERROR(IF(Assumptions!$B$13="Cost Price",AB5,AA5)*SUMIF(Assumptions!$A$6:$A$10,X5,Assumptions!$B$6:$B$10),0) -> 36.475066 | AH5: =IFERROR(IF(Assumptions!$B$13="Cost Price",AB5,AA5)*SUMIF(Assumptions!$A$6:$A$10,X5,Assumptions!$C$6:$C$10),0) -> 22.796916 | AI5: =IFERROR(IF(Assumptions!$B$13="Cost Price",AB5,AA5)*SUMIF(Assumptions!$A$6:$A$10,X5,Assumptions!$D$6:$D$10),0) -> 45.593833 | AJ5: 71.209728 | AK5: =SUM(AG5:AJ5) -> 176.07554 | AL5: 0.33 | AM5: =AC5-AK5 -> 219.71279 | AN5: =IFERROR(AM5/AA5,0) -> 0.48189146 | AO5: =IF(AN5>=Assumptions!$B$3,"OK","Review") -> OK
A6: Corekit AY 2027-2028 | B6: Grade 1 | C6: English | D6: T1_G1_English_WB B2B (27) | E6: 1:1 | F6: Workbook | G6: 2027-2028 | H6: Term 1 | I6: 4000011805 | J6: 20.94 | L6: =J6+K6 -> 20.94 | M6: 0 | N6: =M6*L6 -> 0 | O6: =L6+N6 -> 20.94 | P6: =IFERROR(O6/Q6,"") -> 0.066071372 | Q6: =SUMIFS(O:O,T:T,T6,B:B,B6,A:A,A6,G:G,G6,E:E,E6) -> 316.93 | R6: =V6-SUMIFS(Q:Q,A:A,A6,B:B,B6,G:G,G6,E:E,E6,T:T,"Fixed Price ( Base Price with GST)") -> 2402.3364 | S6: =IF(T6="Fixed Price ( Base Price with GST)",O6,P6*R6) -> 158.72566 | T6: Based on Base % | U6: 4499 | V6: =IFERROR(U6*(1-30%),0) -> 3149.3 | W6: 490110 | X6: Core | Y6: =IFERROR(S6,0) -> 158.72566 | Z6: =IF(ISNUMBER(S6),S6,0) -> 158.72566 | AA6: =IFERROR(Z6/(1+M6),Z6) -> 158.72566 | AB6: =IF(ISNUMBER(J6),J6,0) -> 20.94 | AC6: =AA6-AB6 -> 137.78566 | AD6: =IFERROR(AC6/AA6,0) -> 0.86807426 | AE6: =IFERROR(AC6/AB6,0) -> 6.5800221 | AF6: =IF(AD6>=Assumptions!$B$3,"OK","Review") -> OK | AG6: =IFERROR(IF(Assumptions!$B$13="Cost Price",AB6,AA6)*SUMIF(Assumptions!$A$6:$A$10,X6,Assumptions!$B$6:$B$10),0) -> 12.698053 | AH6: =IFERROR(IF(Assumptions!$B$13="Cost Price",AB6,AA6)*SUMIF(Assumptions!$A$6:$A$10,X6,Assumptions!$C$6:$C$10),0) -> 7.9362831 | AI6: =IFERROR(IF(Assumptions!$B$13="Cost Price",AB6,AA6)*SUMIF(Assumptions!$A$6:$A$10,X6,Assumptions!$D$6:$D$10),0) -> 15.872566 | AJ6: 24.790219 | AK6: =SUM(AG6:AJ6) -> 61.297122 | AL6: 0.33 | AM6: =AC6-AK6 -> 76.488541 | AN6: =IFERROR(AM6/AA6,0) -> 0.48189146 | AO6: =IF(AN6>=Assumptions!$B$3,"OK","Review") -> OK
A7: Corekit AY 2027-2028 | B7: Grade 1 | C7: Maths | D7: T2_G1_Math_Scholars_TB B2B (27) | E7: 1:1 | F7: Book | G7: 2027-2028 | H7: Term 2 | I7: 4000011816 | J7: 46.25 | L7: =J7+K7 -> 46.25 | M7: 0 | N7: =M7*L7 -> 0 | O7: =L7+N7 -> 46.25 | P7: =IFERROR(O7/Q7,"") -> 0.14593128 | Q7: =SUMIFS(O:O,T:T,T7,B:B,B7,A:A,A7,G:G,G7,E:E,E7) -> 316.93 | R7: =V7-SUMIFS(Q:Q,A:A,A7,B:B,B7,G:G,G7,E:E,E7,T:T,"Fixed Price ( Base Price with GST)") -> 2402.3364 | S7: =IF(T7="Fixed Price ( Base Price with GST)",O7,P7*R7) -> 350.57602 | T7: Based on Base % | U7: 4499 | V7: =IFERROR(U7*(1-30%),0) -> 3149.3 | W7: 490110 | X7: Core | Y7: =IFERROR(S7,0) -> 350.57602 | Z7: =IF(ISNUMBER(S7),S7,0) -> 350.57602 | AA7: =IFERROR(Z7/(1+M7),Z7) -> 350.57602 | AB7: =IF(ISNUMBER(J7),J7,0) -> 46.25 | AC7: =AA7-AB7 -> 304.32602 | AD7: =IFERROR(AC7/AA7,0) -> 0.86807426 | AE7: =IFERROR(AC7/AB7,0) -> 6.5800221 | AF7: =IF(AD7>=Assumptions!$B$3,"OK","Review") -> OK | AG7: =IFERROR(IF(Assumptions!$B$13="Cost Price",AB7,AA7)*SUMIF(Assumptions!$A$6:$A$10,X7,Assumptions!$B$6:$B$10),0) -> 28.046082 | AH7: =IFERROR(IF(Assumptions!$B$13="Cost Price",AB7,AA7)*SUMIF(Assumptions!$A$6:$A$10,X7,Assumptions!$C$6:$C$10),0) -> 17.528801 | AI7: =IFERROR(IF(Assumptions!$B$13="Cost Price",AB7,AA7)*SUMIF(Assumptions!$A$6:$A$10,X7,Assumptions!$D$6:$D$10),0) -> 35.057602 | AJ7: 54.753947 | AK7: =SUM(AG7:AJ7) -> 135.38643 | AL7: 0.33 | AM7: =AC7-AK7 -> 168.93959 | AN7: =IFERROR(AM7/AA7,0) -> 0.48189146 | AO7: =IF(AN7>=Assumptions!$B$3,"OK","Review") -> OK
A8: Corekit AY 2027-2028 | B8: Grade 1 | C8: Maths | D8: T2_G1_Math_Scholars_WB B2B (27) | E8: 1:1 | F8: Book | G8: 2027-2028 | H8: Term 2 | I8: 4000011747 | J8: 19.51 | L8: =J8+K8 -> 19.51 | M8: 0 | N8: =M8*L8 -> 0 | O8: =L8+N8 -> 19.51 | P8: =IFERROR(O8/Q8,"") -> 0.061559335 | Q8: =SUMIFS(O:O,T:T,T8,B:B,B8,A:A,A8,G:G,G8,E:E,E8) -> 316.93 | R8: =V8-SUMIFS(Q:Q,A:A,A8,B:B,B8,G:G,G8,E:E,E8,T:T,"Fixed Price ( Base Price with GST)") -> 2402.3364 | S8: =IF(T8="Fixed Price ( Base Price with GST)",O8,P8*R8) -> 147.88623 | T8: Based on Base % | U8: 4499 | V8: =IFERROR(U8*(1-30%),0) -> 3149.3 | W8: 490110 | X8: Core | Y8: =IFERROR(S8,0) -> 147.88623 | Z8: =IF(ISNUMBER(S8),S8,0) -> 147.88623 | AA8: =IFERROR(Z8/(1+M8),Z8) -> 147.88623 | AB8: =IF(ISNUMBER(J8),J8,0) -> 19.51 | AC8: =AA8-AB8 -> 128.37623 | AD8: =IFERROR(AC8/AA8,0) -> 0.86807426 | AE8: =IFERROR(AC8/AB8,0) -> 6.5800221 | AF8: =IF(AD8>=Assumptions!$B$3,"OK","Review") -> OK | AG8: =IFERROR(IF(Assumptions!$B$13="Cost Price",AB8,AA8)*SUMIF(Assumptions!$A$6:$A$10,X8,Assumptions!$B$6:$B$10),0) -> 11.830898 | AH8: =IFERROR(IF(Assumptions!$B$13="Cost Price",AB8,AA8)*SUMIF(Assumptions!$A$6:$A$10,X8,Assumptions!$C$6:$C$10),0) -> 7.3943115 | AI8: =IFERROR(IF(Assumptions!$B$13="Cost Price",AB8,AA8)*SUMIF(Assumptions!$A$6:$A$10,X8,Assumptions!$D$6:$D$10),0) -> 14.788623 | AJ8: 23.097287 | AK8: =SUM(AG8:AJ8) -> 57.11112 | AL8: 0.33 | AM8: =AC8-AK8 -> 71.265111 | AN8: =IFERROR(AM8/AA8,0) -> 0.48189146 | AO8: =IF(AN8>=Assumptions!$B$3,"OK","Review") -> OK
A9: Corekit AY 2027-2028 | B9: Grade 1 | C9: English | D9: T2_G1_English_RC B2B (27) | E9: 1:1 | F9: Workbook | G9: 2027-2028 | H9: Term 2 | I9: 4000011758 | J9: 65.91 | L9: =J9+K9 -> 65.91 | M9: 0 | N9: =M9*L9 -> 0 | O9: =L9+N9 -> 65.91 | P9: =IFERROR(O9/Q9,"") -> 0.2079639 | Q9: =SUMIFS(O:O,T:T,T9,B:B,B9,A:A,A9,G:G,G9,E:E,E9) -> 316.93 | R9: =V9-SUMIFS(Q:Q,A:A,A9,B:B,B9,G:G,G9,E:E,E9,T:T,"Fixed Price ( Base Price with GST)") -> 2402.3364 | S9: =IF(T9="Fixed Price ( Base Price with GST)",O9,P9*R9) -> 499.59926 | T9: Based on Base % | U9: 4499 | V9: =IFERROR(U9*(1-30%),0) -> 3149.3 | W9: 490110 | X9: Core | Y9: =IFERROR(S9,0) -> 499.59926 | Z9: =IF(ISNUMBER(S9),S9,0) -> 499.59926 | AA9: =IFERROR(Z9/(1+M9),Z9) -> 499.59926 | AB9: =IF(ISNUMBER(J9),J9,0) -> 65.91 | AC9: =AA9-AB9 -> 433.68926 | AD9: =IFERROR(AC9/AA9,0) -> 0.86807426 | AE9: =IFERROR(AC9/AB9,0) -> 6.5800221 | AF9: =IF(AD9>=Assumptions!$B$3,"OK","Review") -> OK | AG9: =IFERROR(IF(Assumptions!$B$13="Cost Price",AB9,AA9)*SUMIF(Assumptions!$A$6:$A$10,X9,Assumptions!$B$6:$B$10),0) -> 39.96794 | AH9: =IFERROR(IF(Assumptions!$B$13="Cost Price",AB9,AA9)*SUMIF(Assumptions!$A$6:$A$10,X9,Assumptions!$C$6:$C$10),0) -> 24.979963 | AI9: =IFERROR(IF(Assumptions!$B$13="Cost Price",AB9,AA9)*SUMIF(Assumptions!$A$6:$A$10,X9,Assumptions!$D$6:$D$10),0) -> 49.959926 | AJ9: 78.028814 | AK9: =SUM(AG9:AJ9) -> 192.93664 | AL9: 0.33 | AM9: =AC9-AK9 -> 240.75261 | AN9: =IFERROR(AM9/AA9,0) -> 0.48189146 | AO9: =IF(AN9>=Assumptions!$B$3,"OK","Review") -> OK
A10: Corekit AY 2027-2028 | B10: Grade 1 | C10: English | D10: T2_G1_English_WB B2B (27) | E10: 1:1 | F10: Workbook | G10: 2027-2028 | H10: Term 2 | I10: 4000011769 | J10: 19.51 | L10: =J10+K10 -> 19.51 | M10: 0 | N10: =M10*L10 -> 0 | O10: =L10+N10 -> 19.51 | P10: =IFERROR(O10/Q10,"") -> 0.061559335 | Q10: =SUMIFS(O:O,T:T,T10,B:B,B10,A:A,A10,G:G,G10,E:E,E10) -> 316.93 | R10: =V10-SUMIFS(Q:Q,A:A,A10,B:B,B10,G:G,G10,E:E,E10,T:T,"Fixed Price ( Base Price with GST)") -> 2402.3364 | S10: =IF(T10="Fixed Price ( Base Price with GST)",O10,P10*R10) -> 147.88623 | T10: Based on Base % | U10: 4499 | V10: =IFERROR(U10*(1-30%),0) -> 3149.3 | W10: 490110 | X10: Core | Y10: =IFERROR(S10,0) -> 147.88623 | Z10: =IF(ISNUMBER(S10),S10,0) -> 147.88623 | AA10: =IFERROR(Z10/(1+M10),Z10) -> 147.88623 | AB10: =IF(ISNUMBER(J10),J10,0) -> 19.51 | AC10: =AA10-AB10 -> 128.37623 | AD10: =IFERROR(AC10/AA10,0) -> 0.86807426 | AE10: =IFERROR(AC10/AB10,0) -> 6.5800221 | AF10: =IF(AD10>=Assumptions!$B$3,"OK","Review") -> OK | AG10: =IFERROR(IF(Assumptions!$B$13="Cost Price",AB10,AA10)*SUMIF(Assumptions!$A$6:$A$10,X10,Assumptions!$B$6:$B$10),0) -> 11.830898 | AH10: =IFERROR(IF(Assumptions!$B$13="Cost Price",AB10,AA10)*SUMIF(Assumptions!$A$6:$A$10,X10,Assumptions!$C$6:$C$10),0) -> 7.3943115 | AI10: =IFERROR(IF(Assumptions!$B$13="Cost Price",AB10,AA10)*SUMIF(Assumptions!$A$6:$A$10,X10,Assumptions!$D$6:$D$10),0) -> 14.788623 | AJ10: 23.097287 | AK10: =SUM(AG10:AJ10) -> 57.11112 | AL10: 0.33 | AM10: =AC10-AK10 -> 71.265111 | AN10: =IFERROR(AM10/AA10,0) -> 0.48189146 | AO10: =IF(AN10>=Assumptions!$B$3,"OK","Review") -> OK
A11: Corekit AY 2027-2028 | B11: Grade 1 | C11: Combo Kit | D11: B2B Sci-Pi Visual Maths Kit G1 27-28 | E11: 1:1 | F11: Kit | G11: 2027-2028 | H11: Term 1 | I11: 7000000216 | J11: 210.51 | K11: 10 | L11: =J11+K11 -> 220.51 | M11: 0.18 | N11: =M11*L11 -> 39.6918 | O11: =L11+N11 -> 260.2018 | P11: =IFERROR(O11/Q11,"") -> 0.69669205 | Q11: =SUMIFS(O:O,T:T,T11,B:B,B11,A:A,A11,G:G,G11,E:E,E11) -> 373.4818 | R11: =V11-SUMIFS(Q:Q,A:A,A11,B:B,B11,G:G,G11,E:E,E11,T:T,"Fixed Price ( Base Price with GST)") -> 2402.3364 | S11: =IF(T11="Fixed Price ( Base Price with GST)",O11,P11*R11) -> 260.2018 | T11: Fixed Price ( Base Price with GST) | U11: 4499 | V11: =IFERROR(U11*(1-30%),0) -> 3149.3 | W11: 49119990 | X11: Core | Y11: =IFERROR(S11,0) -> 260.2018 | Z11: =IF(ISNUMBER(S11),S11,0) -> 260.2018 | AA11: =IFERROR(Z11/(1+M11),Z11) -> 220.51 | AB11: =IF(ISNUMBER(J11),J11,0) -> 210.51 | AC11: =AA11-AB11 -> 10 | AD11: =IFERROR(AC11/AA11,0) -> 0.045349417 | AE11: =IFERROR(AC11/AB11,0) -> 0.047503682 | AF11: =IF(AD11>=Assumptions!$B$3,"OK","Review") -> Review | AG11: =IFERROR(IF(Assumptions!$B$13="Cost Price",AB11,AA11)*SUMIF(Assumptions!$A$6:$A$10,X11,Assumptions!$B$6:$B$10),0) -> 17.6408 | AH11: =IFERROR(IF(Assumptions!$B$13="Cost Price",AB11,AA11)*SUMIF(Assumptions!$A$6:$A$10,X11,Assumptions!$C$6:$C$10),0) -> 11.0255 | AI11: =IFERROR(IF(Assumptions!$B$13="Cost Price",AB11,AA11)*SUMIF(Assumptions!$A$6:$A$10,X11,Assumptions!$D$6:$D$10),0) -> 22.051 | AJ11: 22.051 | AK11: =SUM(AG11:AJ11) -> 72.7683 | AL11: 0.33 | AM11: =AC11-AK11 -> -62.7683 | AN11: =IFERROR(AM11/AA11,0) -> -0.28465058 | AO11: =IF(AN11>=Assumptions!$B$3,"OK","Review") -> Review
A12: Corekit AY 2027-2028 | B12: Grade 1 | C12: Service | D12: Services Charges_25_26 | E12: 1:1 | F12: Services Charges | G12: 2027-2028 | H12: Term 1 | I12: 8400007 | J12: 96 | L12: =J12+K12 -> 96 | M12: 0.18 | N12: =M12*L12 -> 17.28 | O12: =L12+N12 -> 113.28 | P12: =IFERROR(O12/Q12,"") -> 0.30330795 | Q12: =SUMIFS(O:O,T:T,T12,B:B,B12,A:A,A12,G:G,G12,E:E,E12) -> 373.4818 | R12: =V12-SUMIFS(Q:Q,A:A,A12,B:B,B12,G:G,G12,E:E,E12,T:T,"Fixed Price ( Base Price with GST)") -> 2402.3364 | S12: =IF(T12="Fixed Price ( Base Price with GST)",O12,P12*R12) -> 113.28 | T12: Fixed Price ( Base Price with GST) | U12: 4499 | V12: =IFERROR(U12*(1-30%),0) -> 3149.3 | W12: 999299 | X12: Core | Y12: =IFERROR(S12,0) -> 113.28 | Z12: =IF(ISNUMBER(S12),S12,0) -> 113.28 | AA12: =IFERROR(Z12/(1+M12),Z12) -> 96 | AB12: =IF(ISNUMBER(J12),J12,0) -> 96 | AC12: =AA12-AB12 -> 0 | AD12: =IFERROR(AC12/AA12,0) -> 0 | AE12: =IFERROR(AC12/AB12,0) -> 0 | AF12: =IF(AD12>=Assumptions!$B$3,"OK","Review") -> Review | AG12: =IFERROR(IF(Assumptions!$B$13="Cost Price",AB12,AA12)*SUMIF(Assumptions!$A$6:$A$10,X12,Assumptions!$B$6:$B$10),0) -> 7.68 | AH12: =IFERROR(IF(Assumptions!$B$13="Cost Price",AB12,AA12)*SUMIF(Assumptions!$A$6:$A$10,X12,Assumptions!$C$6:$C$10),0) -> 4.8 | AI12: =IFERROR(IF(Assumptions!$B$13="Cost Price",AB12,AA12)*SUMIF(Assumptions!$A$6:$A$10,X12,Assumptions!$D$6:$D$10),0) -> 9.6 | AJ12: 9.6 | AK12: =SUM(AG12:AJ12) -> 31.68 | AL12: 0.33 | AM12: =AC12-AK12 -> -31.68 | AN12: =IFERROR(AM12/AA12,0) -> -0.33 | AO12: =IF(AN12>=Assumptions!$B$3,"OK","Review") -> Review
A13: Corekit AY 2027-2028 | B13: Grade 2 | C13: Maths | D13: T1_G2_Math_Scholars_TB B2B (27) | E13: 1:1 | F13: Book | G13: 2027-2028 | H13: Term 1 | I13: 4000011861 | J13: 40.09 | L13: =J13+K13 -> 40.09 | M13: 0 | N13: =M13*L13 -> 0 | O13: =L13+N13 -> 40.09 | P13: =IFERROR(O13/Q13,"") -> 0.12098624 | Q13: =SUMIFS(O:O,T:T,T13,B:B,B13,A:A,A13,G:G,G13,E:E,E13) -> 331.36 | R13: =V13-SUMIFS(Q:Q,A:A,A13,B:B,B13,G:G,G13,E:E,E13,T:T,"Fixed Price ( Base Price with GST)") -> 2387.2088 | S13: =IF(T13="Fixed Price ( Base Price with GST)",O13,P13*R13) -> 288.81941 | T13: Based on Base % | U13: 4499 | V13: =IFERROR(U13*(1-30%),0) -> 3149.3 | W13: 490110 | X13: Core | Y13: =IFERROR(S13,0) -> 288.81941 | Z13: =IF(ISNUMBER(S13),S13,0) -> 288.81941 | AA13: =IFERROR(Z13/(1+M13),Z13) -> 288.81941 | AB13: =IF(ISNUMBER(J13),J13,0) -> 40.09 | AC13: =AA13-AB13 -> 248.72941 | AD13: =IFERROR(AC13/AA13,0) -> 0.86119354 | AE13: =IFERROR(AC13/AB13,0) -> 6.2042757 | AF13: =IF(AD13>=Assumptions!$B$3,"OK","Review") -> OK | AG13: =IFERROR(IF(Assumptions!$B$13="Cost Price",AB13,AA13)*SUMIF(Assumptions!$A$6:$A$10,X13,Assumptions!$B$6:$B$10),0) -> 23.105553 | AH13: =IFERROR(IF(Assumptions!$B$13="Cost Price",AB13,AA13)*SUMIF(Assumptions!$A$6:$A$10,X13,Assumptions!$C$6:$C$10),0) -> 14.440971 | AI13: =IFERROR(IF(Assumptions!$B$13="Cost Price",AB13,AA13)*SUMIF(Assumptions!$A$6:$A$10,X13,Assumptions!$D$6:$D$10),0) -> 28.881941 | AJ13: 45.211454 | AK13: =SUM(AG13:AJ13) -> 111.63992 | AL13: 0.33 | AM13: =AC13-AK13 -> 137.08949 | AN13: =IFERROR(AM13/AA13,0) -> 0.47465471 | AO13: =IF(AN13>=Assumptions!$B$3,"OK","Review") -> OK
A14: Corekit AY 2027-2028 | B14: Grade 2 | C14: Maths | D14: T1_G2_Math_Scholars_WB B2B (27) | E14: 1:1 | F14: Book | G14: 2027-2028 | H14: Term 1 | I14: 4000011872 | J14: 21.01 | L14: =J14+K14 -> 21.01 | M14: 0 | N14: =M14*L14 -> 0 | O14: =L14+N14 -> 21.01 | P14: =IFERROR(O14/Q14,"") -> 0.06340536 | Q14: =SUMIFS(O:O,T:T,T14,B:B,B14,A:A,A14,G:G,G14,E:E,E14) -> 331.36 | R14: =V14-SUMIFS(Q:Q,A:A,A14,B:B,B14,G:G,G14,E:E,E14,T:T,"Fixed Price ( Base Price with GST)") -> 2387.2088 | S14: =IF(T14="Fixed Price ( Base Price with GST)",O14,P14*R14) -> 151.36183 | T14: Based on Base % | U14: 4499 | V14: =IFERROR(U14*(1-30%),0) -> 3149.3 | W14: 490110 | X14: Core | Y14: =IFERROR(S14,0) -> 151.36183 | Z14: =IF(ISNUMBER(S14),S14,0) -> 151.36183 | AA14: =IFERROR(Z14/(1+M14),Z14) -> 151.36183 | AB14: =IF(ISNUMBER(J14),J14,0) -> 21.01 | AC14: =AA14-AB14 -> 130.35183 | AD14: =IFERROR(AC14/AA14,0) -> 0.86119354 | AE14: =IFERROR(AC14/AB14,0) -> 6.2042757 | AF14: =IF(AD14>=Assumptions!$B$3,"OK","Review") -> OK | AG14: =IFERROR(IF(Assumptions!$B$13="Cost Price",AB14,AA14)*SUMIF(Assumptions!$A$6:$A$10,X14,Assumptions!$B$6:$B$10),0) -> 12.108947 | AH14: =IFERROR(IF(Assumptions!$B$13="Cost Price",AB14,AA14)*SUMIF(Assumptions!$A$6:$A$10,X14,Assumptions!$C$6:$C$10),0) -> 7.5680916 | AI14: =IFERROR(IF(Assumptions!$B$13="Cost Price",AB14,AA14)*SUMIF(Assumptions!$A$6:$A$10,X14,Assumptions!$D$6:$D$10),0) -> 15.136183 | AJ14: 23.694005 | AK14: =SUM(AG14:AJ14) -> 58.507226 | AL14: 0.33 | AM14: =AC14-AK14 -> 71.844607 | AN14: =IFERROR(AM14/AA14,0) -> 0.47465471 | AO14: =IF(AN14>=Assumptions!$B$3,"OK","Review") -> OK
A15: Corekit AY 2027-2028 | B15: Grade 2 | C15: English | D15: Annual_G2_English_RB B2B (27) | E15: 1:1 | F15: Book | G15: 2027-2028 | H15: Term 1 | I15: 4000011837 | J15: 20.1 | L15: =J15+K15 -> 20.1 | M15: 0 | N15: =M15*L15 -> 0 | O15: =L15+N15 -> 20.1 | P15: =IFERROR(O15/Q15,"") -> 0.060659102 | Q15: =SUMIFS(O:O,T:T,T15,B:B,B15,A:A,A15,G:G,G15,E:E,E15) -> 331.36 | R15: =V15-SUMIFS(Q:Q,A:A,A15,B:B,B15,G:G,G15,E:E,E15,T:T,"Fixed Price ( Base Price with GST)") -> 2387.2088 | S15: =IF(T15="Fixed Price ( Base Price with GST)",O15,P15*R15) -> 144.80594 | T15: Based on Base % | U15: 4499 | V15: =IFERROR(U15*(1-30%),0) -> 3149.3 | W15: 490110 | X15: Core | Y15: =IFERROR(S15,0) -> 144.80594 | Z15: =IF(ISNUMBER(S15),S15,0) -> 144.80594 | AA15: =IFERROR(Z15/(1+M15),Z15) -> 144.80594 | AB15: =IF(ISNUMBER(J15),J15,0) -> 20.1 | AC15: =AA15-AB15 -> 124.70594 | AD15: =IFERROR(AC15/AA15,0) -> 0.86119354 | AE15: =IFERROR(AC15/AB15,0) -> 6.2042757 | AF15: =IF(AD15>=Assumptions!$B$3,"OK","Review") -> OK | AG15: =IFERROR(IF(Assumptions!$B$13="Cost Price",AB15,AA15)*SUMIF(Assumptions!$A$6:$A$10,X15,Assumptions!$B$6:$B$10),0) -> 11.584475 | AH15: =IFERROR(IF(Assumptions!$B$13="Cost Price",AB15,AA15)*SUMIF(Assumptions!$A$6:$A$10,X15,Assumptions!$C$6:$C$10),0) -> 7.2402971 | AI15: =IFERROR(IF(Assumptions!$B$13="Cost Price",AB15,AA15)*SUMIF(Assumptions!$A$6:$A$10,X15,Assumptions!$D$6:$D$10),0) -> 14.480594 | AJ15: 22.667753 | AK15: =SUM(AG15:AJ15) -> 55.97312 | AL15: 0.33 | AM15: =AC15-AK15 -> 68.732822 | AN15: =IFERROR(AM15/AA15,0) -> 0.47465471 | AO15: =IF(AN15>=Assumptions!$B$3,"OK","Review") -> OK
A16: Corekit AY 2027-2028 | B16: Grade 2 | C16: English | D16: T1_G2_English_RC B2B (27) | E16: 1:1 | F16: Workbook | G16: 2027-2028 | H16: Term 1 | I16: 4000011826 | J16: 66.38 | L16: =J16+K16 -> 66.38 | M16: 0 | N16: =M16*L16 -> 0 | O16: =L16+N16 -> 66.38 | P16: =IFERROR(O16/Q16,"") -> 0.20032593 | Q16: =SUMIFS(O:O,T:T,T16,B:B,B16,A:A,A16,G:G,G16,E:E,E16) -> 331.36 | R16: =V16-SUMIFS(Q:Q,A:A,A16,B:B,B16,G:G,G16,E:E,E16,T:T,"Fixed Price ( Base Price with GST)") -> 2387.2088 | S16: =IF(T16="Fixed Price ( Base Price with GST)",O16,P16*R16) -> 478.21982 | T16: Based on Base % | U16: 4499 | V16: =IFERROR(U16*(1-30%),0) -> 3149.3 | W16: 490110 | X16: Core | Y16: =IFERROR(S16,0) -> 478.21982 | Z16: =IF(ISNUMBER(S16),S16,0) -> 478.21982 | AA16: =IFERROR(Z16/(1+M16),Z16) -> 478.21982 | AB16: =IF(ISNUMBER(J16),J16,0) -> 66.38 | AC16: =AA16-AB16 -> 411.83982 | AD16: =IFERROR(AC16/AA16,0) -> 0.86119354 | AE16: =IFERROR(AC16/AB16,0) -> 6.2042757 | AF16: =IF(AD16>=Assumptions!$B$3,"OK","Review") -> OK | AG16: =IFERROR(IF(Assumptions!$B$13="Cost Price",AB16,AA16)*SUMIF(Assumptions!$A$6:$A$10,X16,Assumptions!$B$6:$B$10),0) -> 38.257586 | AH16: =IFERROR(IF(Assumptions!$B$13="Cost Price",AB16,AA16)*SUMIF(Assumptions!$A$6:$A$10,X16,Assumptions!$C$6:$C$10),0) -> 23.910991 | AI16: =IFERROR(IF(Assumptions!$B$13="Cost Price",AB16,AA16)*SUMIF(Assumptions!$A$6:$A$10,X16,Assumptions!$D$6:$D$10),0) -> 47.821982 | AJ16: 74.859973 | AK16: =SUM(AG16:AJ16) -> 184.85053 | AL16: 0.33 | AM16: =AC16-AK16 -> 226.98929 | AN16: =IFERROR(AM16/AA16,0) -> 0.47465471 | AO16: =IF(AN16>=Assumptions!$B$3,"OK","Review") -> OK
A17: Corekit AY 2027-2028 | B17: Grade 2 | C17: English | D17: T1_G2_English_WB B2B (27) | E17: 1:1 | F17: Workbook | G17: 2027-2028 | H17: Term 1 | I17: 4000011846 | J17: 25.48 | L17: =J17+K17 -> 25.48 | M17: 0 | N17: =M17*L17 -> 0 | O17: =L17+N17 -> 25.48 | P17: =IFERROR(O17/Q17,"") -> 0.07689522 | Q17: =SUMIFS(O:O,T:T,T17,B:B,B17,A:A,A17,G:G,G17,E:E,E17) -> 331.36 | R17: =V17-SUMIFS(Q:Q,A:A,A17,B:B,B17,G:G,G17,E:E,E17,T:T,"Fixed Price ( Base Price with GST)") -> 2387.2088 | S17: =IF(T17="Fixed Price ( Base Price with GST)",O17,P17*R17) -> 183.56495 | T17: Based on Base % | U17: 4499 | V17: =IFERROR(U17*(1-30%),0) -> 3149.3 | W17: 490110 | X17: Core | Y17: =IFERROR(S17,0) -> 183.56495 | Z17: =IF(ISNUMBER(S17),S17,0) -> 183.56495 | AA17: =IFERROR(Z17/(1+M17),Z17) -> 183.56495 | AB17: =IF(ISNUMBER(J17),J17,0) -> 25.48 | AC17: =AA17-AB17 -> 158.08495 | AD17: =IFERROR(AC17/AA17,0) -> 0.86119354 | AE17: =IFERROR(AC17/AB17,0) -> 6.2042757 | AF17: =IF(AD17>=Assumptions!$B$3,"OK","Review") -> OK | AG17: =IFERROR(IF(Assumptions!$B$13="Cost Price",AB17,AA17)*SUMIF(Assumptions!$A$6:$A$10,X17,Assumptions!$B$6:$B$10),0) -> 14.685196 | AH17: =IFERROR(IF(Assumptions!$B$13="Cost Price",AB17,AA17)*SUMIF(Assumptions!$A$6:$A$10,X17,Assumptions!$C$6:$C$10),0) -> 9.1782473 | AI17: =IFERROR(IF(Assumptions!$B$13="Cost Price",AB17,AA17)*SUMIF(Assumptions!$A$6:$A$10,X17,Assumptions!$D$6:$D$10),0) -> 18.356495 | AJ17: 28.735042 | AK17: =SUM(AG17:AJ17) -> 70.95498 | AL17: 0.33 | AM17: =AC17-AK17 -> 87.129965 | AN17: =IFERROR(AM17/AA17,0) -> 0.47465471 | AO17: =IF(AN17>=Assumptions!$B$3,"OK","Review") -> OK
A18: Corekit AY 2027-2028 | B18: Grade 2 | C18: Maths | D18: T2_G2_Math_Scholars_TB B2B (27) | E18: 1:1 | F18: Book | G18: 2027-2028 | H18: Term 2 | I18: 4000011847 | J18: 50.5 | L18: =J18+K18 -> 50.5 | M18: 0 | N18: =M18*L18 -> 0 | O18: =L18+N18 -> 50.5 | P18: =IFERROR(O18/Q18,"") -> 0.15240222 | Q18: =SUMIFS(O:O,T:T,T18,B:B,B18,A:A,A18,G:G,G18,E:E,E18) -> 331.36 | R18: =V18-SUMIFS(Q:Q,A:A,A18,B:B,B18,G:G,G18,E:E,E18,T:T,"Fixed Price ( Base Price with GST)") -> 2387.2088 | S18: =IF(T18="Fixed Price ( Base Price with GST)",O18,P18*R18) -> 363.81592 | T18: Based on Base % | U18: 4499 | V18: =IFERROR(U18*(1-30%),0) -> 3149.3 | W18: 490110 | X18: Core | Y18: =IFERROR(S18,0) -> 363.81592 | Z18: =IF(ISNUMBER(S18),S18,0) -> 363.81592 | AA18: =IFERROR(Z18/(1+M18),Z18) -> 363.81592 | AB18: =IF(ISNUMBER(J18),J18,0) -> 50.5 | AC18: =AA18-AB18 -> 313.31592 | AD18: =IFERROR(AC18/AA18,0) -> 0.86119354 | AE18: =IFERROR(AC18/AB18,0) -> 6.2042757 | AF18: =IF(AD18>=Assumptions!$B$3,"OK","Review") -> OK | AG18: =IFERROR(IF(Assumptions!$B$13="Cost Price",AB18,AA18)*SUMIF(Assumptions!$A$6:$A$10,X18,Assumptions!$B$6:$B$10),0) -> 29.105274 | AH18: =IFERROR(IF(Assumptions!$B$13="Cost Price",AB18,AA18)*SUMIF(Assumptions!$A$6:$A$10,X18,Assumptions!$C$6:$C$10),0) -> 18.190796 | AI18: =IFERROR(IF(Assumptions!$B$13="Cost Price",AB18,AA18)*SUMIF(Assumptions!$A$6:$A$10,X18,Assumptions!$D$6:$D$10),0) -> 36.381592 | AJ18: 56.95132 | AK18: =SUM(AG18:AJ18) -> 140.62898 | AL18: 0.33 | AM18: =AC18-AK18 -> 172.68694 | AN18: =IFERROR(AM18/AA18,0) -> 0.47465471 | AO18: =IF(AN18>=Assumptions!$B$3,"OK","Review") -> OK
A19: Corekit AY 2027-2028 | B19: Grade 2 | C19: Maths | D19: T2_G2_Math_Scholars_WB B2B (27) | E19: 1:1 | F19: Book | G19: 2027-2028 | H19: Term 2 | I19: 4000011848 | J19: 21.01 | L19: =J19+K19 -> 21.01 | M19: 0 | N19: =M19*L19 -> 0 | O19: =L19+N19 -> 21.01 | P19: =IFERROR(O19/Q19,"") -> 0.06340536 | Q19: =SUMIFS(O:O,T:T,T19,B:B,B19,A:A,A19,G:G,G19,E:E,E19) -> 331.36 | R19: =V19-SUMIFS(Q:Q,A:A,A19,B:B,B19,G:G,G19,E:E,E19,T:T,"Fixed Price ( Base Price with GST)") -> 2387.2088 | S19: =IF(T19="Fixed Price ( Base Price with GST)",O19,P19*R19) -> 151.36183 | T19: Based on Base % | U19: 4499 | V19: =IFERROR(U19*(1-30%),0) -> 3149.3 | W19: 490110 | X19: Core | Y19: =IFERROR(S19,0) -> 151.36183 | Z19: =IF(ISNUMBER(S19),S19,0) -> 151.36183 | AA19: =IFERROR(Z19/(1+M19),Z19) -> 151.36183 | AB19: =IF(ISNUMBER(J19),J19,0) -> 21.01 | AC19: =AA19-AB19 -> 130.35183 | AD19: =IFERROR(AC19/AA19,0) -> 0.86119354 | AE19: =IFERROR(AC19/AB19,0) -> 6.2042757 | AF19: =IF(AD19>=Assumptions!$B$3,"OK","Review") -> OK | AG19: =IFERROR(IF(Assumptions!$B$13="Cost Price",AB19,AA19)*SUMIF(Assumptions!$A$6:$A$10,X19,Assumptions!$B$6:$B$10),0) -> 12.108947 | AH19: =IFERROR(IF(Assumptions!$B$13="Cost Price",AB19,AA19)*SUMIF(Assumptions!$A$6:$A$10,X19,Assumptions!$C$6:$C$10),0) -> 7.5680916 | AI19: =IFERROR(IF(Assumptions!$B$13="Cost Price",AB19,AA19)*SUMIF(Assumptions!$A$6:$A$10,X19,Assumptions!$D$6:$D$10),0) -> 15.136183 | AJ19: 23.694005 | AK19: =SUM(AG19:AJ19) -> 58.507226 | AL19: 0.33 | AM19: =AC19-AK19 -> 71.844607 | AN19: =IFERROR(AM19/AA19,0) -> 0.47465471 | AO19: =IF(AN19>=Assumptions!$B$3,"OK","Review") -> OK
A20: Corekit AY 2027-2028 | B20: Grade 2 | C20: English | D20: T2_G2_English_RC B2B (27) | E20: 1:1 | F20: Workbook | G20: 2027-2028 | H20: Term 2 | I20: 4000011849 | J20: 62.84 | L20: =J20+K20 -> 62.84 | M20: 0 | N20: =M20*L20 -> 0 | O20: =L20+N20 -> 62.84 | P20: =IFERROR(O20/Q20,"") -> 0.18964268 | Q20: =SUMIFS(O:O,T:T,T20,B:B,B20,A:A,A20,G:G,G20,E:E,E20) -> 331.36 | R20: =V20-SUMIFS(Q:Q,A:A,A20,B:B,B20,G:G,G20,E:E,E20,T:T,"Fixed Price ( Base Price with GST)") -> 2387.2088 | S20: =IF(T20="Fixed Price ( Base Price with GST)",O20,P20*R20) -> 452.71669 | T20: Based on Base % | U20: 4499 | V20: =IFERROR(U20*(1-30%),0) -> 3149.3 | W20: 490110 | X20: Core | Y20: =IFERROR(S20,0) -> 452.71669 | Z20: =IF(ISNUMBER(S20),S20,0) -> 452.71669 | AA20: =IFERROR(Z20/(1+M20),Z20) -> 452.71669 | AB20: =IF(ISNUMBER(J20),J20,0) -> 62.84 | AC20: =AA20-AB20 -> 389.87669 | AD20: =IFERROR(AC20/AA20,0) -> 0.86119354 | AE20: =IFERROR(AC20/AB20,0) -> 6.2042757 | AF20: =IF(AD20>=Assumptions!$B$3,"OK","Review") -> OK | AG20: =IFERROR(IF(Assumptions!$B$13="Cost Price",AB20,AA20)*SUMIF(Assumptions!$A$6:$A$10,X20,Assumptions!$B$6:$B$10),0) -> 36.217335 | AH20: =IFERROR(IF(Assumptions!$B$13="Cost Price",AB20,AA20)*SUMIF(Assumptions!$A$6:$A$10,X20,Assumptions!$C$6:$C$10),0) -> 22.635834 | AI20: =IFERROR(IF(Assumptions!$B$13="Cost Price",AB20,AA20)*SUMIF(Assumptions!$A$6:$A$10,X20,Assumptions!$D$6:$D$10),0) -> 45.271669 | AJ20: 70.867742 | AK20: =SUM(AG20:AJ20) -> 174.99258 | AL20: 0.33 | AM20: =AC20-AK20 -> 214.88411 | AN20: =IFERROR(AM20/AA20,0) -> 0.47465471 | AO20: =IF(AN20>=Assumptions!$B$3,"OK","Review") -> OK
A21: Corekit AY 2027-2028 | B21: Grade 2 | C21: English | D21: T2_G2_English_WB B2B (27) | E21: 1:1 | F21: Workbook | G21: 2027-2028 | H21: Term 2 | I21: 4000011850 | J21: 23.95 | L21: =J21+K21 -> 23.95 | M21: 0 | N21: =M21*L21 -> 0 | O21: =L21+N21 -> 23.95 | P21: =IFERROR(O21/Q21,"") -> 0.072277885 | Q21: =SUMIFS(O:O,T:T,T21,B:B,B21,A:A,A21,G:G,G21,E:E,E21) -> 331.36 | R21: =V21-SUMIFS(Q:Q,A:A,A21,B:B,B21,G:G,G21,E:E,E21,T:T,"Fixed Price ( Base Price with GST)") -> 2387.2088 | S21: =IF(T21="Fixed Price ( Base Price with GST)",O21,P21*R21) -> 172.5424 | T21: Based on Base % | U21: 4499 | V21: =IFERROR(U21*(1-30%),0) -> 3149.3 | W21: 490110 | X21: Core | Y21: =IFERROR(S21,0) -> 172.5424 | Z21: =IF(ISNUMBER(S21),S21,0) -> 172.5424 | AA21: =IFERROR(Z21/(1+M21),Z21) -> 172.5424 | AB21: =IF(ISNUMBER(J21),J21,0) -> 23.95 | AC21: =AA21-AB21 -> 148.5924 | AD21: =IFERROR(AC21/AA21,0) -> 0.86119354 | AE21: =IFERROR(AC21/AB21,0) -> 6.2042757 | AF21: =IF(AD21>=Assumptions!$B$3,"OK","Review") -> OK | AG21: =IFERROR(IF(Assumptions!$B$13="Cost Price",AB21,AA21)*SUMIF(Assumptions!$A$6:$A$10,X21,Assumptions!$B$6:$B$10),0) -> 13.803392 | AH21: =IFERROR(IF(Assumptions!$B$13="Cost Price",AB21,AA21)*SUMIF(Assumptions!$A$6:$A$10,X21,Assumptions!$C$6:$C$10),0) -> 8.6271202 | AI21: =IFERROR(IF(Assumptions!$B$13="Cost Price",AB21,AA21)*SUMIF(Assumptions!$A$6:$A$10,X21,Assumptions!$D$6:$D$10),0) -> 17.25424 | AJ21: 27.009586 | AK21: =SUM(AG21:AJ21) -> 66.694339 | AL21: 0.33 | AM21: =AC21-AK21 -> 81.898064 | AN21: =IFERROR(AM21/AA21,0) -> 0.47465471 | AO21: =IF(AN21>=Assumptions!$B$3,"OK","Review") -> OK
